[2023-03-17 00:04:32,030] {taskinstance.py:1159} INFO - Dependencies all met for <TaskInstance: reto_tecnico_everst.download_data scheduled__2023-03-16T23:00:00+00:00 [queued]>
[2023-03-17 00:04:32,042] {taskinstance.py:1159} INFO - Dependencies all met for <TaskInstance: reto_tecnico_everst.download_data scheduled__2023-03-16T23:00:00+00:00 [queued]>
[2023-03-17 00:04:32,044] {taskinstance.py:1356} INFO - 
--------------------------------------------------------------------------------
[2023-03-17 00:04:32,045] {taskinstance.py:1357} INFO - Starting attempt 1 of 1
[2023-03-17 00:04:32,046] {taskinstance.py:1358} INFO - 
--------------------------------------------------------------------------------
[2023-03-17 00:04:32,318] {taskinstance.py:1377} INFO - Executing <Task(PythonOperator): download_data> on 2023-03-16 23:00:00+00:00
[2023-03-17 00:04:32,323] {standard_task_runner.py:52} INFO - Started process 191 to run task
[2023-03-17 00:04:32,326] {standard_task_runner.py:79} INFO - Running: ['***', 'tasks', 'run', 'reto_tecnico_everst', 'download_data', 'scheduled__2023-03-16T23:00:00+00:00', '--job-id', '119', '--raw', '--subdir', 'DAGS_FOLDER/reto_tecnico_everst.py', '--cfg-path', '/tmp/tmp5n3jkmio', '--error-file', '/tmp/tmpd4m_6xs1']
[2023-03-17 00:04:32,327] {standard_task_runner.py:80} INFO - Job 119: Subtask download_data
[2023-03-17 00:04:32,520] {task_command.py:369} INFO - Running <TaskInstance: reto_tecnico_everst.download_data scheduled__2023-03-16T23:00:00+00:00 [running]> on host 7d9c3e4a2f58
[2023-03-17 00:04:32,892] {taskinstance.py:1571} INFO - Exporting the following env vars:
AIRFLOW_CTX_DAG_OWNER=***
AIRFLOW_CTX_DAG_ID=reto_tecnico_everst
AIRFLOW_CTX_TASK_ID=download_data
AIRFLOW_CTX_EXECUTION_DATE=2023-03-16T23:00:00+00:00
AIRFLOW_CTX_TRY_NUMBER=1
AIRFLOW_CTX_DAG_RUN_ID=scheduled__2023-03-16T23:00:00+00:00
[2023-03-17 00:04:36,087] {reto_tecnico_everst.py:36} ERROR - Se genero un Error al intentar conectar con la url: https://smn.conagua.gob.mx/webservices/index.php?method=3
[2023-03-17 00:04:36,087] {taskinstance.py:1889} ERROR - Task failed with exception
Traceback (most recent call last):
  File "/opt/airflow/dags/reto_tecnico_everst.py", line 34, in download_data
    gz_content = urlopen(request_site).read()
  File "/usr/local/lib/python3.7/urllib/request.py", line 222, in urlopen
    return opener.open(url, data, timeout)
  File "/usr/local/lib/python3.7/urllib/request.py", line 531, in open
    response = meth(req, response)
  File "/usr/local/lib/python3.7/urllib/request.py", line 641, in http_response
    'http', request, response, code, msg, hdrs)
  File "/usr/local/lib/python3.7/urllib/request.py", line 563, in error
    result = self._call_chain(*args)
  File "/usr/local/lib/python3.7/urllib/request.py", line 503, in _call_chain
    result = func(*args)
  File "/usr/local/lib/python3.7/urllib/request.py", line 755, in http_error_302
    return self.parent.open(new, timeout=req.timeout)
  File "/usr/local/lib/python3.7/urllib/request.py", line 531, in open
    response = meth(req, response)
  File "/usr/local/lib/python3.7/urllib/request.py", line 641, in http_response
    'http', request, response, code, msg, hdrs)
  File "/usr/local/lib/python3.7/urllib/request.py", line 569, in error
    return self._call_chain(*args)
  File "/usr/local/lib/python3.7/urllib/request.py", line 503, in _call_chain
    result = func(*args)
  File "/usr/local/lib/python3.7/urllib/request.py", line 649, in http_error_default
    raise HTTPError(req.full_url, code, msg, hdrs, fp)
urllib.error.HTTPError: HTTP Error 404: Not Found

During handling of the above exception, another exception occurred:

Traceback (most recent call last):
  File "/home/airflow/.local/lib/python3.7/site-packages/airflow/operators/python.py", line 171, in execute
    return_value = self.execute_callable()
  File "/home/airflow/.local/lib/python3.7/site-packages/airflow/operators/python.py", line 189, in execute_callable
    return self.python_callable(*self.op_args, **self.op_kwargs)
  File "/opt/airflow/dags/reto_tecnico_everst.py", line 37, in download_data
    raise AirflowFailException(e)
airflow.exceptions.AirflowFailException: HTTP Error 404: Not Found
[2023-03-17 00:04:36,312] {taskinstance.py:1400} INFO - Immediate failure requested. Marking task as FAILED. dag_id=reto_tecnico_everst, task_id=download_data, execution_date=20230316T230000, start_date=20230317T000432, end_date=20230317T000436
[2023-03-17 00:04:37,849] {standard_task_runner.py:97} ERROR - Failed to execute job 119 for task download_data (HTTP Error 404: Not Found; 191)
[2023-03-17 00:04:37,896] {local_task_job.py:156} INFO - Task exited with return code 1
[2023-03-17 00:04:38,098] {local_task_job.py:273} INFO - 0 downstream tasks scheduled from follow-on schedule check
[2023-03-17 00:09:02,293] {taskinstance.py:1159} INFO - Dependencies all met for <TaskInstance: reto_tecnico_everst.download_data scheduled__2023-03-16T23:00:00+00:00 [queued]>
[2023-03-17 00:09:02,303] {taskinstance.py:1159} INFO - Dependencies all met for <TaskInstance: reto_tecnico_everst.download_data scheduled__2023-03-16T23:00:00+00:00 [queued]>
[2023-03-17 00:09:02,304] {taskinstance.py:1356} INFO - 
--------------------------------------------------------------------------------
[2023-03-17 00:09:02,304] {taskinstance.py:1357} INFO - Starting attempt 1 of 1
[2023-03-17 00:09:02,304] {taskinstance.py:1358} INFO - 
--------------------------------------------------------------------------------
[2023-03-17 00:09:02,385] {taskinstance.py:1377} INFO - Executing <Task(PythonOperator): download_data> on 2023-03-16 23:00:00+00:00
[2023-03-17 00:09:02,396] {standard_task_runner.py:52} INFO - Started process 279 to run task
[2023-03-17 00:09:02,409] {standard_task_runner.py:79} INFO - Running: ['***', 'tasks', 'run', 'reto_tecnico_everst', 'download_data', 'scheduled__2023-03-16T23:00:00+00:00', '--job-id', '125', '--raw', '--subdir', 'DAGS_FOLDER/reto_tecnico_everst.py', '--cfg-path', '/tmp/tmphutjutmb', '--error-file', '/tmp/tmp542scteg']
[2023-03-17 00:09:02,411] {standard_task_runner.py:80} INFO - Job 125: Subtask download_data
[2023-03-17 00:09:02,545] {task_command.py:369} INFO - Running <TaskInstance: reto_tecnico_everst.download_data scheduled__2023-03-16T23:00:00+00:00 [running]> on host 7d9c3e4a2f58
[2023-03-17 00:09:02,723] {taskinstance.py:1571} INFO - Exporting the following env vars:
AIRFLOW_CTX_DAG_OWNER=***
AIRFLOW_CTX_DAG_ID=reto_tecnico_everst
AIRFLOW_CTX_TASK_ID=download_data
AIRFLOW_CTX_EXECUTION_DATE=2023-03-16T23:00:00+00:00
AIRFLOW_CTX_TRY_NUMBER=1
AIRFLOW_CTX_DAG_RUN_ID=scheduled__2023-03-16T23:00:00+00:00
[2023-03-17 00:09:06,203] {reto_tecnico_everst.py:38} INFO - Generando descarga del GZ
[2023-03-17 00:09:09,794] {reto_tecnico_everst.py:45} INFO - Guardando la base generada desde el API, path: dags/data/Raw/base_api/base_20230317_00.09.json
[2023-03-17 00:09:23,390] {python.py:173} INFO - Done. Returned value was: None
[2023-03-17 00:09:23,419] {taskinstance.py:1400} INFO - Marking task as SUCCESS. dag_id=reto_tecnico_everst, task_id=download_data, execution_date=20230316T230000, start_date=20230317T000902, end_date=20230317T000923
[2023-03-17 00:09:23,597] {local_task_job.py:156} INFO - Task exited with return code 0
[2023-03-17 00:09:23,651] {local_task_job.py:273} INFO - 2 downstream tasks scheduled from follow-on schedule check
