[2023-03-17 20:50:17,460] {taskinstance.py:1159} INFO - Dependencies all met for <TaskInstance: reto_tecnico_everst.table_by_municipio manual__2023-03-17T20:49:54.810410+00:00 [queued]>
[2023-03-17 20:50:17,468] {taskinstance.py:1159} INFO - Dependencies all met for <TaskInstance: reto_tecnico_everst.table_by_municipio manual__2023-03-17T20:49:54.810410+00:00 [queued]>
[2023-03-17 20:50:17,469] {taskinstance.py:1356} INFO - 
--------------------------------------------------------------------------------
[2023-03-17 20:50:17,470] {taskinstance.py:1357} INFO - Starting attempt 1 of 1
[2023-03-17 20:50:17,470] {taskinstance.py:1358} INFO - 
--------------------------------------------------------------------------------
[2023-03-17 20:50:17,525] {taskinstance.py:1377} INFO - Executing <Task(PythonOperator): table_by_municipio> on 2023-03-17 20:49:54.810410+00:00
[2023-03-17 20:50:17,543] {standard_task_runner.py:52} INFO - Started process 4374 to run task
[2023-03-17 20:50:17,546] {standard_task_runner.py:79} INFO - Running: ['***', 'tasks', 'run', 'reto_tecnico_everst', 'table_by_municipio', 'manual__2023-03-17T20:49:54.810410+00:00', '--job-id', '232', '--raw', '--subdir', 'DAGS_FOLDER/reto_tecnico_everst.py', '--cfg-path', '/tmp/tmpp4dpz2_t', '--error-file', '/tmp/tmpa8nc0uwq']
[2023-03-17 20:50:17,548] {standard_task_runner.py:80} INFO - Job 232: Subtask table_by_municipio
[2023-03-17 20:50:17,628] {task_command.py:369} INFO - Running <TaskInstance: reto_tecnico_everst.table_by_municipio manual__2023-03-17T20:49:54.810410+00:00 [running]> on host 7d9c3e4a2f58
[2023-03-17 20:50:17,821] {taskinstance.py:1571} INFO - Exporting the following env vars:
AIRFLOW_CTX_DAG_OWNER=***
AIRFLOW_CTX_DAG_ID=reto_tecnico_everst
AIRFLOW_CTX_TASK_ID=table_by_municipio
AIRFLOW_CTX_EXECUTION_DATE=2023-03-17T20:49:54.810410+00:00
AIRFLOW_CTX_TRY_NUMBER=1
AIRFLOW_CTX_DAG_RUN_ID=manual__2023-03-17T20:49:54.810410+00:00
[2023-03-17 20:50:17,911] {reto_tecnico_everst.py:57} INFO - Leyendo la base extraida del API
[2023-03-17 20:50:21,188] {reto_tecnico_everst.py:70} INFO - Formateando los tipos de datos en el DataFrame.
[2023-03-17 20:50:21,191] {taskinstance.py:1889} ERROR - Task failed with exception
Traceback (most recent call last):
  File "/home/airflow/.local/lib/python3.7/site-packages/airflow/operators/python.py", line 171, in execute
    return_value = self.execute_callable()
  File "/home/airflow/.local/lib/python3.7/site-packages/airflow/operators/python.py", line 189, in execute_callable
    return self.python_callable(*self.op_args, **self.op_kwargs)
  File "/opt/airflow/dags/reto_tecnico_everst.py", line 71, in table_by_municipio
    n_df['temp'] = n_df['temp'].astype(np.int64)
  File "/home/airflow/.local/lib/python3.7/site-packages/pandas/core/generic.py", line 5815, in astype
    new_data = self._mgr.astype(dtype=dtype, copy=copy, errors=errors)
  File "/home/airflow/.local/lib/python3.7/site-packages/pandas/core/internals/managers.py", line 418, in astype
    return self.apply("astype", dtype=dtype, copy=copy, errors=errors)
  File "/home/airflow/.local/lib/python3.7/site-packages/pandas/core/internals/managers.py", line 327, in apply
    applied = getattr(b, f)(**kwargs)
  File "/home/airflow/.local/lib/python3.7/site-packages/pandas/core/internals/blocks.py", line 591, in astype
    new_values = astype_array_safe(values, dtype, copy=copy, errors=errors)
  File "/home/airflow/.local/lib/python3.7/site-packages/pandas/core/dtypes/cast.py", line 1309, in astype_array_safe
    new_values = astype_array(values, dtype, copy=copy)
  File "/home/airflow/.local/lib/python3.7/site-packages/pandas/core/dtypes/cast.py", line 1257, in astype_array
    values = astype_nansafe(values, dtype, copy=copy)
  File "/home/airflow/.local/lib/python3.7/site-packages/pandas/core/dtypes/cast.py", line 1174, in astype_nansafe
    return lib.astype_intsafe(arr, dtype)
  File "pandas/_libs/lib.pyx", line 679, in pandas._libs.lib.astype_intsafe
ValueError: invalid literal for int() with base 10: '28.40'
[2023-03-17 20:50:21,220] {taskinstance.py:1400} INFO - Marking task as FAILED. dag_id=reto_tecnico_everst, task_id=table_by_municipio, execution_date=20230317T204954, start_date=20230317T205017, end_date=20230317T205021
[2023-03-17 20:50:21,342] {standard_task_runner.py:97} ERROR - Failed to execute job 232 for task table_by_municipio (invalid literal for int() with base 10: '28.40'; 4374)
[2023-03-17 20:50:21,413] {local_task_job.py:156} INFO - Task exited with return code 1
[2023-03-17 20:50:21,474] {local_task_job.py:273} INFO - 0 downstream tasks scheduled from follow-on schedule check
