[2023-03-16 23:02:02,998] {taskinstance.py:1159} INFO - Dependencies all met for <TaskInstance: reto_tecnico_everst.download_data manual__2023-03-16T23:02:01.339029+00:00 [queued]>
[2023-03-16 23:02:03,007] {taskinstance.py:1159} INFO - Dependencies all met for <TaskInstance: reto_tecnico_everst.download_data manual__2023-03-16T23:02:01.339029+00:00 [queued]>
[2023-03-16 23:02:03,008] {taskinstance.py:1356} INFO - 
--------------------------------------------------------------------------------
[2023-03-16 23:02:03,009] {taskinstance.py:1357} INFO - Starting attempt 1 of 1
[2023-03-16 23:02:03,009] {taskinstance.py:1358} INFO - 
--------------------------------------------------------------------------------
[2023-03-16 23:02:03,066] {taskinstance.py:1377} INFO - Executing <Task(PythonOperator): download_data> on 2023-03-16 23:02:01.339029+00:00
[2023-03-16 23:02:03,082] {standard_task_runner.py:52} INFO - Started process 2050 to run task
[2023-03-16 23:02:03,097] {standard_task_runner.py:79} INFO - Running: ['***', 'tasks', 'run', 'reto_tecnico_everst', 'download_data', 'manual__2023-03-16T23:02:01.339029+00:00', '--job-id', '116', '--raw', '--subdir', 'DAGS_FOLDER/reto_tecnico_everst.py', '--cfg-path', '/tmp/tmpah4glg6n', '--error-file', '/tmp/tmpgltsn0ws']
[2023-03-16 23:02:03,099] {standard_task_runner.py:80} INFO - Job 116: Subtask download_data
[2023-03-16 23:02:03,245] {task_command.py:369} INFO - Running <TaskInstance: reto_tecnico_everst.download_data manual__2023-03-16T23:02:01.339029+00:00 [running]> on host 7d9c3e4a2f58
[2023-03-16 23:02:03,536] {taskinstance.py:1571} INFO - Exporting the following env vars:
AIRFLOW_CTX_DAG_OWNER=***
AIRFLOW_CTX_DAG_ID=reto_tecnico_everst
AIRFLOW_CTX_TASK_ID=download_data
AIRFLOW_CTX_EXECUTION_DATE=2023-03-16T23:02:01.339029+00:00
AIRFLOW_CTX_TRY_NUMBER=1
AIRFLOW_CTX_DAG_RUN_ID=manual__2023-03-16T23:02:01.339029+00:00
[2023-03-16 23:02:05,279] {reto_tecnico_everst.py:36} ERROR - Se genero un Error al intentar conectar con la url: https://smn.conagua.gob.mx/webservices/index.php?method=3
[2023-03-16 23:02:05,280] {taskinstance.py:1889} ERROR - Task failed with exception
Traceback (most recent call last):
  File "/opt/airflow/dags/reto_tecnico_everst.py", line 34, in download_data
    gz_content = urlopen(request_site).read()
  File "/usr/local/lib/python3.7/urllib/request.py", line 222, in urlopen
    return opener.open(url, data, timeout)
  File "/usr/local/lib/python3.7/urllib/request.py", line 531, in open
    response = meth(req, response)
  File "/usr/local/lib/python3.7/urllib/request.py", line 641, in http_response
    'http', request, response, code, msg, hdrs)
  File "/usr/local/lib/python3.7/urllib/request.py", line 563, in error
    result = self._call_chain(*args)
  File "/usr/local/lib/python3.7/urllib/request.py", line 503, in _call_chain
    result = func(*args)
  File "/usr/local/lib/python3.7/urllib/request.py", line 755, in http_error_302
    return self.parent.open(new, timeout=req.timeout)
  File "/usr/local/lib/python3.7/urllib/request.py", line 531, in open
    response = meth(req, response)
  File "/usr/local/lib/python3.7/urllib/request.py", line 641, in http_response
    'http', request, response, code, msg, hdrs)
  File "/usr/local/lib/python3.7/urllib/request.py", line 569, in error
    return self._call_chain(*args)
  File "/usr/local/lib/python3.7/urllib/request.py", line 503, in _call_chain
    result = func(*args)
  File "/usr/local/lib/python3.7/urllib/request.py", line 649, in http_error_default
    raise HTTPError(req.full_url, code, msg, hdrs, fp)
urllib.error.HTTPError: HTTP Error 404: Not Found

During handling of the above exception, another exception occurred:

Traceback (most recent call last):
  File "/home/airflow/.local/lib/python3.7/site-packages/airflow/operators/python.py", line 171, in execute
    return_value = self.execute_callable()
  File "/home/airflow/.local/lib/python3.7/site-packages/airflow/operators/python.py", line 189, in execute_callable
    return self.python_callable(*self.op_args, **self.op_kwargs)
  File "/opt/airflow/dags/reto_tecnico_everst.py", line 37, in download_data
    raise AirflowFailException(e)
airflow.exceptions.AirflowFailException: HTTP Error 404: Not Found
[2023-03-16 23:02:05,307] {taskinstance.py:1400} INFO - Immediate failure requested. Marking task as FAILED. dag_id=reto_tecnico_everst, task_id=download_data, execution_date=20230316T230201, start_date=20230316T230202, end_date=20230316T230205
[2023-03-16 23:02:05,422] {standard_task_runner.py:97} ERROR - Failed to execute job 116 for task download_data (HTTP Error 404: Not Found; 2050)
[2023-03-16 23:02:05,468] {local_task_job.py:156} INFO - Task exited with return code 1
[2023-03-16 23:02:05,563] {local_task_job.py:273} INFO - 0 downstream tasks scheduled from follow-on schedule check
