[2023-03-17 20:49:22,050] {taskinstance.py:1159} INFO - Dependencies all met for <TaskInstance: reto_tecnico_everst.get_last_data_municipios scheduled__2023-03-17T19:00:00+00:00 [queued]>
[2023-03-17 20:49:22,060] {taskinstance.py:1159} INFO - Dependencies all met for <TaskInstance: reto_tecnico_everst.get_last_data_municipios scheduled__2023-03-17T19:00:00+00:00 [queued]>
[2023-03-17 20:49:22,061] {taskinstance.py:1356} INFO - 
--------------------------------------------------------------------------------
[2023-03-17 20:49:22,061] {taskinstance.py:1357} INFO - Starting attempt 1 of 1
[2023-03-17 20:49:22,061] {taskinstance.py:1358} INFO - 
--------------------------------------------------------------------------------
[2023-03-17 20:49:22,110] {taskinstance.py:1377} INFO - Executing <Task(PythonOperator): get_last_data_municipios> on 2023-03-17 19:00:00+00:00
[2023-03-17 20:49:22,125] {standard_task_runner.py:52} INFO - Started process 4349 to run task
[2023-03-17 20:49:22,133] {standard_task_runner.py:79} INFO - Running: ['***', 'tasks', 'run', 'reto_tecnico_everst', 'get_last_data_municipios', 'scheduled__2023-03-17T19:00:00+00:00', '--job-id', '227', '--raw', '--subdir', 'DAGS_FOLDER/reto_tecnico_everst.py', '--cfg-path', '/tmp/tmprhcfw0hn', '--error-file', '/tmp/tmp8_mvoi8a']
[2023-03-17 20:49:22,135] {standard_task_runner.py:80} INFO - Job 227: Subtask get_last_data_municipios
[2023-03-17 20:49:22,374] {task_command.py:369} INFO - Running <TaskInstance: reto_tecnico_everst.get_last_data_municipios scheduled__2023-03-17T19:00:00+00:00 [running]> on host 7d9c3e4a2f58
[2023-03-17 20:49:22,683] {taskinstance.py:1571} INFO - Exporting the following env vars:
AIRFLOW_CTX_DAG_OWNER=***
AIRFLOW_CTX_DAG_ID=reto_tecnico_everst
AIRFLOW_CTX_TASK_ID=get_last_data_municipios
AIRFLOW_CTX_EXECUTION_DATE=2023-03-17T19:00:00+00:00
AIRFLOW_CTX_TRY_NUMBER=1
AIRFLOW_CTX_DAG_RUN_ID=scheduled__2023-03-17T19:00:00+00:00
[2023-03-17 20:49:22,701] {taskinstance.py:1889} ERROR - Task failed with exception
Traceback (most recent call last):
  File "/home/airflow/.local/lib/python3.7/site-packages/airflow/operators/python.py", line 171, in execute
    return_value = self.execute_callable()
  File "/home/airflow/.local/lib/python3.7/site-packages/airflow/operators/python.py", line 189, in execute_callable
    return self.python_callable(*self.op_args, **self.op_kwargs)
TypeError: get_last_data_municipios() takes 0 positional arguments but 1 was given
[2023-03-17 20:49:22,767] {taskinstance.py:1400} INFO - Marking task as FAILED. dag_id=reto_tecnico_everst, task_id=get_last_data_municipios, execution_date=20230317T190000, start_date=20230317T204922, end_date=20230317T204922
[2023-03-17 20:49:22,873] {standard_task_runner.py:97} ERROR - Failed to execute job 227 for task get_last_data_municipios (get_last_data_municipios() takes 0 positional arguments but 1 was given; 4349)
[2023-03-17 20:49:22,914] {local_task_job.py:156} INFO - Task exited with return code 1
[2023-03-17 20:49:22,977] {local_task_job.py:273} INFO - 0 downstream tasks scheduled from follow-on schedule check
