[2023-03-17 19:00:23,485] {taskinstance.py:1159} INFO - Dependencies all met for <TaskInstance: reto_tecnico_everst.create_data_municipios scheduled__2023-03-17T18:00:00+00:00 [queued]>
[2023-03-17 19:00:23,497] {taskinstance.py:1159} INFO - Dependencies all met for <TaskInstance: reto_tecnico_everst.create_data_municipios scheduled__2023-03-17T18:00:00+00:00 [queued]>
[2023-03-17 19:00:23,498] {taskinstance.py:1356} INFO - 
--------------------------------------------------------------------------------
[2023-03-17 19:00:23,499] {taskinstance.py:1357} INFO - Starting attempt 1 of 1
[2023-03-17 19:00:23,499] {taskinstance.py:1358} INFO - 
--------------------------------------------------------------------------------
[2023-03-17 19:00:23,630] {taskinstance.py:1377} INFO - Executing <Task(PythonOperator): create_data_municipios> on 2023-03-17 18:00:00+00:00
[2023-03-17 19:00:23,647] {standard_task_runner.py:52} INFO - Started process 2625 to run task
[2023-03-17 19:00:23,652] {standard_task_runner.py:79} INFO - Running: ['***', 'tasks', 'run', 'reto_tecnico_everst', 'create_data_municipios', 'scheduled__2023-03-17T18:00:00+00:00', '--job-id', '225', '--raw', '--subdir', 'DAGS_FOLDER/reto_tecnico_everst.py', '--cfg-path', '/tmp/tmpibo3jyie', '--error-file', '/tmp/tmpq9tpj93y']
[2023-03-17 19:00:23,654] {standard_task_runner.py:80} INFO - Job 225: Subtask create_data_municipios
[2023-03-17 19:00:23,783] {task_command.py:369} INFO - Running <TaskInstance: reto_tecnico_everst.create_data_municipios scheduled__2023-03-17T18:00:00+00:00 [running]> on host 7d9c3e4a2f58
[2023-03-17 19:00:24,085] {taskinstance.py:1571} INFO - Exporting the following env vars:
AIRFLOW_CTX_DAG_OWNER=***
AIRFLOW_CTX_DAG_ID=reto_tecnico_everst
AIRFLOW_CTX_TASK_ID=create_data_municipios
AIRFLOW_CTX_EXECUTION_DATE=2023-03-17T18:00:00+00:00
AIRFLOW_CTX_TRY_NUMBER=1
AIRFLOW_CTX_DAG_RUN_ID=scheduled__2023-03-17T18:00:00+00:00
[2023-03-17 19:00:29,109] {taskinstance.py:1889} ERROR - Task failed with exception
Traceback (most recent call last):
  File "/home/airflow/.local/lib/python3.7/site-packages/airflow/operators/python.py", line 171, in execute
    return_value = self.execute_callable()
  File "/home/airflow/.local/lib/python3.7/site-packages/airflow/operators/python.py", line 189, in execute_callable
    return self.python_callable(*self.op_args, **self.op_kwargs)
  File "/opt/airflow/dags/reto_tecnico_everst.py", line 84, in create_data_municipios
    lst_max_date = [max_date] * len(list_municipios)
TypeError: object of type 'NoneType' has no len()
[2023-03-17 19:00:29,138] {taskinstance.py:1400} INFO - Marking task as FAILED. dag_id=reto_tecnico_everst, task_id=create_data_municipios, execution_date=20230317T180000, start_date=20230317T190023, end_date=20230317T190029
[2023-03-17 19:00:29,219] {standard_task_runner.py:97} ERROR - Failed to execute job 225 for task create_data_municipios (object of type 'NoneType' has no len(); 2625)
[2023-03-17 19:00:29,250] {local_task_job.py:156} INFO - Task exited with return code 1
[2023-03-17 19:00:29,318] {local_task_job.py:273} INFO - 0 downstream tasks scheduled from follow-on schedule check
